{
 "cells": [
  {
   "cell_type": "code",
   "execution_count": 1,
   "metadata": {},
   "outputs": [],
   "source": [
    "import torch, torchvision\n",
    "import torchvision.transforms as transforms\n",
    "from torch.utils.data import DataLoader\n",
    "from torchvision.datasets import CIFAR10\n",
    "\n",
    "from bgan.cnnTrainer import CnnTrainer\n",
    "from bgan.wcnnTrainer import WcnnTrainer\n",
    "from bgan.vatCnnTrainer import VatCnnTrainer\n",
    "from bgan.networkparts import *\n",
    "import bgan.augLayers as augLayers\n",
    "%matplotlib inline\n",
    "%load_ext autoreload\n",
    "%autoreload 2"
   ]
  },
  {
   "cell_type": "markdown",
   "metadata": {},
   "source": [
    "## CNN Configuration"
   ]
  },
  {
   "cell_type": "code",
   "execution_count": 2,
   "metadata": {},
   "outputs": [],
   "source": [
    "savedir = '/home/maf388/tb-experiments/layer13wAugTransf2/'\n",
    "config = {'lr':1e-4, 'amntLab':4000, \n",
    "          'lab_BS':32}\n",
    "\n",
    "baseCNN = layer13(numClasses=10)\n",
    "\n",
    "fullCNN = nn.Sequential(\n",
    "#     augLayers.RandomTranslate(4),\n",
    "#     augLayers.RandomHorizontalFlip(),\n",
    "    augLayers.GaussianNoise(0.15),\n",
    "    baseCNN,\n",
    ")"
   ]
  },
  {
   "cell_type": "markdown",
   "metadata": {},
   "source": [
    "## Dataset"
   ]
  },
  {
   "cell_type": "code",
   "execution_count": 3,
   "metadata": {},
   "outputs": [
    {
     "name": "stdout",
     "output_type": "stream",
     "text": [
      "Files already downloaded and verified\n",
      "Files already downloaded and verified\n"
     ]
    }
   ],
   "source": [
    "img_size = 32\n",
    "transform_dev = transforms.Compose(\n",
    "    [transforms.Resize(img_size),\n",
    "     transforms.ToTensor(),\n",
    "     transforms.Normalize((0.4914, 0.4822, 0.4465), (0.2023, 0.1994, 0.2010))])\n",
    "\n",
    "transform_train = transform_dev\n",
    "transform_train = transforms.Compose(\n",
    "    [transforms.RandomCrop(32, padding=4),\n",
    "     transforms.RandomHorizontalFlip(),\n",
    "     transform_dev])\n",
    "\n",
    "pathToDataset = '/scratch/datasets/cifar10/'\n",
    "trainset = CIFAR10(pathToDataset, download=True, transform=transform_train)\n",
    "devset = CIFAR10(pathToDataset, train=False, download=True, transform=transform_dev)\n",
    "testset = None\n",
    "\n",
    "datasets = (trainset, devset, testset)"
   ]
  },
  {
   "cell_type": "code",
   "execution_count": 10,
   "metadata": {},
   "outputs": [
    {
     "name": "stderr",
     "output_type": "stream",
     "text": [
      "Process Process-13:\n",
      "Process Process-14:\n",
      "Traceback (most recent call last):\n",
      "Traceback (most recent call last):\n",
      "  File \"/home/maf388/.conda/envs/env0/lib/python3.5/multiprocessing/process.py\", line 252, in _bootstrap\n",
      "    self.run()\n",
      "  File \"/home/maf388/.conda/envs/env0/lib/python3.5/multiprocessing/process.py\", line 252, in _bootstrap\n",
      "    self.run()\n",
      "  File \"/home/maf388/.conda/envs/env0/lib/python3.5/multiprocessing/process.py\", line 93, in run\n",
      "    self._target(*self._args, **self._kwargs)\n",
      "  File \"/home/maf388/.conda/envs/env0/lib/python3.5/site-packages/torch/utils/data/dataloader.py\", line 50, in _worker_loop\n",
      "    r = index_queue.get()\n",
      "  File \"/home/maf388/.conda/envs/env0/lib/python3.5/multiprocessing/process.py\", line 93, in run\n",
      "    self._target(*self._args, **self._kwargs)\n",
      "  File \"/home/maf388/.conda/envs/env0/lib/python3.5/site-packages/torch/utils/data/dataloader.py\", line 50, in _worker_loop\n",
      "    r = index_queue.get()\n",
      "  File \"/home/maf388/.conda/envs/env0/lib/python3.5/multiprocessing/queues.py\", line 335, in get\n",
      "    res = self._reader.recv_bytes()\n",
      "  File \"/home/maf388/.conda/envs/env0/lib/python3.5/multiprocessing/connection.py\", line 216, in recv_bytes\n",
      "    buf = self._recv_bytes(maxlength)\n",
      "  File \"/home/maf388/.conda/envs/env0/lib/python3.5/multiprocessing/queues.py\", line 334, in get\n",
      "    with self._rlock:\n",
      "  File \"/home/maf388/.conda/envs/env0/lib/python3.5/multiprocessing/connection.py\", line 407, in _recv_bytes\n",
      "    buf = self._recv(4)\n",
      "  File \"/home/maf388/.conda/envs/env0/lib/python3.5/multiprocessing/synchronize.py\", line 96, in __enter__\n",
      "    return self._semlock.__enter__()\n",
      "  File \"/home/maf388/.conda/envs/env0/lib/python3.5/multiprocessing/connection.py\", line 379, in _recv\n",
      "    chunk = read(handle, remaining)\n",
      "KeyboardInterrupt\n",
      "KeyboardInterrupt\n"
     ]
    }
   ],
   "source": [
    "trainer = CnnTrainer(fullCNN,datasets,savedir,**config)"
   ]
  },
  {
   "cell_type": "code",
   "execution_count": null,
   "metadata": {
    "scrolled": true
   },
   "outputs": [
    {
     "name": "stdout",
     "output_type": "stream",
     "text": [
      "[  0/640][     0/80000] Train_Acc(Batch): 0.094 Val_Acc: 0.100 \n"
     ]
    },
    {
     "name": "stderr",
     "output_type": "stream",
     "text": [
      "--- Logging error ---\n",
      "Traceback (most recent call last):\n",
      "  File \"/home/maf388/.conda/envs/env0/lib/python3.5/site-packages/IPython/core/interactiveshell.py\", line 2910, in run_code\n",
      "    exec(code_obj, self.user_global_ns, self.user_ns)\n",
      "  File \"<ipython-input-11-0efafca1f2eb>\", line 1, in <module>\n",
      "    trainer.train(640)\n",
      "  File \"/home/maf388/bayesganfuture/bgan/cnnTrainer.py\", line 56, in train\n",
      "    trainData = to_var_gpu(next(self.train_iter))\n",
      "  File \"/home/maf388/bayesganfuture/bgan/utils.py\", line 11, in to_var_gpu\n",
      "    return type(x)(map(to_var_gpu, x))\n",
      "  File \"/home/maf388/bayesganfuture/bgan/utils.py\", line 13, in to_var_gpu\n",
      "    return Variable(x).cuda()\n",
      "  File \"/home/maf388/.conda/envs/env0/lib/python3.5/site-packages/torch/autograd/variable.py\", line 298, in cuda\n",
      "    return CudaTransfer.apply(self, device, async)\n",
      "  File \"/home/maf388/.conda/envs/env0/lib/python3.5/site-packages/torch/autograd/_functions/tensor.py\", line 201, in forward\n",
      "    return i.cuda(async=async)\n",
      "  File \"/home/maf388/.conda/envs/env0/lib/python3.5/site-packages/torch/_utils.py\", line 69, in _cuda\n",
      "    return new_type(self.size()).copy_(self, async)\n",
      "KeyboardInterrupt\n",
      "\n",
      "During handling of the above exception, another exception occurred:\n",
      "\n",
      "Traceback (most recent call last):\n",
      "  File \"/home/maf388/.conda/envs/env0/lib/python3.5/site-packages/IPython/core/interactiveshell.py\", line 1828, in showtraceback\n",
      "    stb = value._render_traceback_()\n",
      "AttributeError: 'KeyboardInterrupt' object has no attribute '_render_traceback_'\n",
      "\n",
      "During handling of the above exception, another exception occurred:\n",
      "\n",
      "Traceback (most recent call last):\n",
      "  File \"/home/maf388/.conda/envs/env0/lib/python3.5/site-packages/IPython/core/ultratb.py\", line 1090, in get_records\n",
      "    return _fixed_getinnerframes(etb, number_of_lines_of_context, tb_offset)\n",
      "  File \"/home/maf388/.conda/envs/env0/lib/python3.5/site-packages/IPython/core/ultratb.py\", line 311, in wrapped\n",
      "    return f(*args, **kwargs)\n",
      "  File \"/home/maf388/.conda/envs/env0/lib/python3.5/site-packages/IPython/core/ultratb.py\", line 345, in _fixed_getinnerframes\n",
      "    records = fix_frame_records_filenames(inspect.getinnerframes(etb, context))\n",
      "  File \"/home/maf388/.conda/envs/env0/lib/python3.5/inspect.py\", line 1459, in getinnerframes\n",
      "    frameinfo = (tb.tb_frame,) + getframeinfo(tb, context)\n",
      "  File \"/home/maf388/.conda/envs/env0/lib/python3.5/inspect.py\", line 1421, in getframeinfo\n",
      "    lines, lnum = findsource(frame)\n",
      "  File \"/home/maf388/.conda/envs/env0/lib/python3.5/site-packages/IPython/core/ultratb.py\", line 177, in findsource\n",
      "    lines = linecache.getlines(file, globals_dict)\n",
      "  File \"/home/maf388/.conda/envs/env0/lib/python3.5/linecache.py\", line 47, in getlines\n",
      "    return updatecache(filename, module_globals)\n",
      "  File \"/home/maf388/.conda/envs/env0/lib/python3.5/linecache.py\", line 136, in updatecache\n",
      "    with tokenize.open(fullname) as fp:\n",
      "  File \"/home/maf388/.conda/envs/env0/lib/python3.5/tokenize.py\", line 456, in open\n",
      "    encoding, lines = detect_encoding(buffer.readline)\n",
      "  File \"/home/maf388/.conda/envs/env0/lib/python3.5/tokenize.py\", line 425, in detect_encoding\n",
      "    first = read_or_stop()\n",
      "  File \"/home/maf388/.conda/envs/env0/lib/python3.5/tokenize.py\", line 383, in read_or_stop\n",
      "    return readline()\n",
      "  File \"/home/maf388/.conda/envs/env0/lib/python3.5/site-packages/torch/utils/data/dataloader.py\", line 175, in handler\n",
      "    _error_if_any_worker_fails()\n",
      "RuntimeError: DataLoader worker (pid 22365) exited unexpectedly with exit code 1.\n",
      "\n",
      "During handling of the above exception, another exception occurred:\n",
      "\n",
      "Traceback (most recent call last):\n",
      "  File \"/home/maf388/.conda/envs/env0/lib/python3.5/site-packages/IPython/core/interactiveshell.py\", line 2856, in run_ast_nodes\n",
      "    if self.run_code(code, result):\n",
      "  File \"/home/maf388/.conda/envs/env0/lib/python3.5/site-packages/IPython/core/interactiveshell.py\", line 2927, in run_code\n",
      "    self.showtraceback(running_compiled_code=True)\n",
      "  File \"/home/maf388/.conda/envs/env0/lib/python3.5/site-packages/IPython/core/interactiveshell.py\", line 1831, in showtraceback\n",
      "    value, tb, tb_offset=tb_offset)\n",
      "  File \"/home/maf388/.conda/envs/env0/lib/python3.5/site-packages/IPython/core/ultratb.py\", line 1371, in structured_traceback\n",
      "    self, etype, value, tb, tb_offset, number_of_lines_of_context)\n",
      "  File \"/home/maf388/.conda/envs/env0/lib/python3.5/site-packages/IPython/core/ultratb.py\", line 1279, in structured_traceback\n",
      "    self, etype, value, tb, tb_offset, number_of_lines_of_context\n",
      "  File \"/home/maf388/.conda/envs/env0/lib/python3.5/site-packages/IPython/core/ultratb.py\", line 1128, in structured_traceback\n",
      "    tb_offset)\n",
      "  File \"/home/maf388/.conda/envs/env0/lib/python3.5/site-packages/IPython/core/ultratb.py\", line 1066, in format_exception_as_a_whole\n",
      "    records = self.get_records(etb, number_of_lines_of_context, tb_offset)\n",
      "  File \"/home/maf388/.conda/envs/env0/lib/python3.5/site-packages/IPython/core/ultratb.py\", line 1105, in get_records\n",
      "    traceback.print_exc(file=self.ostream)\n",
      "  File \"/home/maf388/.conda/envs/env0/lib/python3.5/traceback.py\", line 159, in print_exc\n",
      "    print_exception(*sys.exc_info(), limit=limit, file=file, chain=chain)\n",
      "  File \"/home/maf388/.conda/envs/env0/lib/python3.5/traceback.py\", line 100, in print_exception\n",
      "    type(value), value, tb, limit=limit).format(chain=chain):\n",
      "  File \"/home/maf388/.conda/envs/env0/lib/python3.5/traceback.py\", line 463, in __init__\n",
      "    _seen=_seen)\n",
      "  File \"/home/maf388/.conda/envs/env0/lib/python3.5/traceback.py\", line 463, in __init__\n",
      "    _seen=_seen)\n",
      "  File \"/home/maf388/.conda/envs/env0/lib/python3.5/traceback.py\", line 474, in __init__\n",
      "    capture_locals=capture_locals)\n",
      "  File \"/home/maf388/.conda/envs/env0/lib/python3.5/traceback.py\", line 354, in extract\n",
      "    linecache.checkcache(filename)\n",
      "  File \"/home/maf388/.conda/envs/env0/lib/python3.5/site-packages/IPython/core/compilerop.py\", line 140, in check_linecache_ipython\n",
      "    linecache._checkcache_ori(*args)\n",
      "  File \"/home/maf388/.conda/envs/env0/lib/python3.5/linecache.py\", line 74, in checkcache\n",
      "    stat = os.stat(fullname)\n",
      "  File \"/home/maf388/.conda/envs/env0/lib/python3.5/site-packages/torch/utils/data/dataloader.py\", line 175, in handler\n",
      "    _error_if_any_worker_fails()\n",
      "RuntimeError: DataLoader worker (pid 24541) exited unexpectedly with exit code 1.\n",
      "\n",
      "During handling of the above exception, another exception occurred:\n",
      "\n",
      "Traceback (most recent call last):\n",
      "  File \"/home/maf388/.conda/envs/env0/lib/python3.5/site-packages/ipykernel/kernelbase.py\", line 235, in dispatch_shell\n",
      "    handler(stream, idents, msg)\n",
      "  File \"/home/maf388/.conda/envs/env0/lib/python3.5/site-packages/ipykernel/kernelbase.py\", line 399, in execute_request\n",
      "    user_expressions, allow_stdin)\n",
      "  File \"/home/maf388/.conda/envs/env0/lib/python3.5/site-packages/ipykernel/ipkernel.py\", line 196, in do_execute\n",
      "    res = shell.run_cell(code, store_history=store_history, silent=silent)\n",
      "  File \"/home/maf388/.conda/envs/env0/lib/python3.5/site-packages/ipykernel/zmqshell.py\", line 533, in run_cell\n",
      "    return super(ZMQInteractiveShell, self).run_cell(*args, **kwargs)\n",
      "  File \"/home/maf388/.conda/envs/env0/lib/python3.5/site-packages/IPython/core/interactiveshell.py\", line 2728, in run_cell\n",
      "    interactivity=interactivity, compiler=compiler, result=result)\n",
      "  File \"/home/maf388/.conda/envs/env0/lib/python3.5/site-packages/IPython/core/interactiveshell.py\", line 2874, in run_ast_nodes\n",
      "    result.error_before_exec = sys.exc_info()[1]\n",
      "  File \"/home/maf388/.conda/envs/env0/lib/python3.5/site-packages/torch/utils/data/dataloader.py\", line 175, in handler\n",
      "    _error_if_any_worker_fails()\n",
      "RuntimeError: DataLoader worker (pid 27567) exited unexpectedly with exit code 1.\n",
      "\n",
      "During handling of the above exception, another exception occurred:\n",
      "\n",
      "Traceback (most recent call last):\n",
      "  File \"/home/maf388/.conda/envs/env0/lib/python3.5/logging/__init__.py\", line 986, in emit\n",
      "    msg = self.format(record)\n",
      "  File \"/home/maf388/.conda/envs/env0/lib/python3.5/logging/__init__.py\", line 836, in format\n",
      "    return fmt.format(record)\n",
      "  File \"/home/maf388/.conda/envs/env0/lib/python3.5/site-packages/traitlets/config/application.py\", line 117, in format\n",
      "    return super(LevelFormatter, self).format(record)\n",
      "  File \"/home/maf388/.conda/envs/env0/lib/python3.5/logging/__init__.py\", line 581, in format\n",
      "    record.exc_text = self.formatException(record.exc_info)\n",
      "  File \"/home/maf388/.conda/envs/env0/lib/python3.5/logging/__init__.py\", line 531, in formatException\n",
      "    traceback.print_exception(ei[0], ei[1], tb, None, sio)\n",
      "  File \"/home/maf388/.conda/envs/env0/lib/python3.5/traceback.py\", line 100, in print_exception\n",
      "    type(value), value, tb, limit=limit).format(chain=chain):\n",
      "  File \"/home/maf388/.conda/envs/env0/lib/python3.5/traceback.py\", line 487, in __init__\n",
      "    self._load_lines()\n",
      "  File \"/home/maf388/.conda/envs/env0/lib/python3.5/traceback.py\", line 500, in _load_lines\n",
      "    self.__context__._load_lines()\n",
      "  File \"/home/maf388/.conda/envs/env0/lib/python3.5/traceback.py\", line 498, in _load_lines\n",
      "    frame.line\n",
      "  File \"/home/maf388/.conda/envs/env0/lib/python3.5/traceback.py\", line 282, in line\n",
      "    self._line = linecache.getline(self.filename, self.lineno).strip()\n",
      "  File \"/home/maf388/.conda/envs/env0/lib/python3.5/linecache.py\", line 16, in getline\n",
      "    lines = getlines(filename, module_globals)\n",
      "  File \"/home/maf388/.conda/envs/env0/lib/python3.5/linecache.py\", line 47, in getlines\n",
      "    return updatecache(filename, module_globals)\n",
      "  File \"/home/maf388/.conda/envs/env0/lib/python3.5/linecache.py\", line 136, in updatecache\n",
      "    with tokenize.open(fullname) as fp:\n",
      "  File \"/home/maf388/.conda/envs/env0/lib/python3.5/tokenize.py\", line 454, in open\n",
      "    buffer = _builtin_open(filename, 'rb')\n",
      "  File \"/home/maf388/.conda/envs/env0/lib/python3.5/site-packages/torch/utils/data/dataloader.py\", line 175, in handler\n",
      "    _error_if_any_worker_fails()\n",
      "RuntimeError: DataLoader worker (pid 25475) exited unexpectedly with exit code 1.\n",
      "Call stack:\n",
      "  File \"/home/maf388/.conda/envs/env0/lib/python3.5/runpy.py\", line 193, in _run_module_as_main\n",
      "    \"__main__\", mod_spec)\n",
      "  File \"/home/maf388/.conda/envs/env0/lib/python3.5/runpy.py\", line 85, in _run_code\n",
      "    exec(code, run_globals)\n",
      "  File \"/home/maf388/.conda/envs/env0/lib/python3.5/site-packages/ipykernel_launcher.py\", line 16, in <module>\n",
      "    app.launch_new_instance()\n",
      "  File \"/home/maf388/.conda/envs/env0/lib/python3.5/site-packages/traitlets/config/application.py\", line 658, in launch_instance\n",
      "    app.start()\n",
      "  File \"/home/maf388/.conda/envs/env0/lib/python3.5/site-packages/ipykernel/kernelapp.py\", line 477, in start\n",
      "    ioloop.IOLoop.instance().start()\n",
      "  File \"/home/maf388/.conda/envs/env0/lib/python3.5/site-packages/zmq/eventloop/ioloop.py\", line 177, in start\n",
      "    super(ZMQIOLoop, self).start()\n",
      "  File \"/home/maf388/.conda/envs/env0/lib/python3.5/site-packages/tornado/ioloop.py\", line 888, in start\n",
      "    handler_func(fd_obj, events)\n",
      "  File \"/home/maf388/.conda/envs/env0/lib/python3.5/site-packages/tornado/stack_context.py\", line 277, in null_wrapper\n",
      "    return fn(*args, **kwargs)\n",
      "  File \"/home/maf388/.conda/envs/env0/lib/python3.5/site-packages/zmq/eventloop/zmqstream.py\", line 440, in _handle_events\n",
      "    self._handle_recv()\n",
      "  File \"/home/maf388/.conda/envs/env0/lib/python3.5/site-packages/zmq/eventloop/zmqstream.py\", line 472, in _handle_recv\n",
      "    self._run_callback(callback, msg)\n",
      "  File \"/home/maf388/.conda/envs/env0/lib/python3.5/site-packages/zmq/eventloop/zmqstream.py\", line 414, in _run_callback\n",
      "    callback(*args, **kwargs)\n",
      "  File \"/home/maf388/.conda/envs/env0/lib/python3.5/site-packages/tornado/stack_context.py\", line 277, in null_wrapper\n",
      "    return fn(*args, **kwargs)\n",
      "  File \"/home/maf388/.conda/envs/env0/lib/python3.5/site-packages/ipykernel/kernelbase.py\", line 283, in dispatcher\n",
      "    return self.dispatch_shell(stream, msg)\n",
      "  File \"/home/maf388/.conda/envs/env0/lib/python3.5/site-packages/ipykernel/kernelbase.py\", line 237, in dispatch_shell\n",
      "    self.log.error(\"Exception in message handler:\", exc_info=True)\n",
      "Message: 'Exception in message handler:'\n",
      "Arguments: ()\n"
     ]
    }
   ],
   "source": [
    "trainer.train(640)"
   ]
  },
  {
   "cell_type": "code",
   "execution_count": null,
   "metadata": {},
   "outputs": [],
   "source": [
    "trainer.CNN.training"
   ]
  },
  {
   "cell_type": "code",
   "execution_count": null,
   "metadata": {},
   "outputs": [],
   "source": []
  }
 ],
 "metadata": {
  "kernelspec": {
   "display_name": "Python 3",
   "language": "python",
   "name": "python3"
  },
  "language_info": {
   "codemirror_mode": {
    "name": "ipython",
    "version": 3
   },
   "file_extension": ".py",
   "mimetype": "text/x-python",
   "name": "python",
   "nbconvert_exporter": "python",
   "pygments_lexer": "ipython3",
   "version": "3.5.4"
  }
 },
 "nbformat": 4,
 "nbformat_minor": 2
}
